Workbook

Sheet RAW_Forecast_Data
A1: Rep_ID | B1: Rep_Name | C1: Segment | D1: Week_Ending_Date | E1: Quarter | F1: Forecasted_Revenue | G1: Actual_Revenue_Closed | H1: Pipeline_Value | I1: Weighted_Pipeline | J1: Stage_Distribution | K1: Deal_Count_Forecasted | L1: Deal_Count_Closed | M1: Forecast_Submitted_On_Time | N1: Notes
A2: E01 | B2: James Whitfield | C2: Enterprise | D2: 05/01/2024 | E2: Q1 2024 | F2: 83501.51 | G2: 80495.84 | H2: 237882.83 | I2: 72771.57 | J2: Qualify:20%,Propose:20%,Negotiate:40%,Close:20% | K2: 5 | L2: 4 | M2: Y
A3: E02 | B3: Sarah Thornton | C3: Enterprise | D3: 2024-01-05 | E3: Jan-Mar 2024 | F3: 101890.04 | G3: 187730.93 | H3: 432558.75 | I3: 89293.76 | J3: Qualify:10%,Propose:35%,Negotiate:40%,Close:15% | K3: 3 | L3: 3 | M3: Y | N3: Verbal commit received – awaiting paperwork
A4: E03 | B4: Marcus Bellingham | C4: enterprise | D4: 05/01/2024 | E4: Q1 2024 | F4: 196116.65 | G4: 199835.64 | H4: 773362.56 | I4: 145229.87 | J4: Qualify:20%,Propose:20%,Negotiate:40%,Close:20% | K4: 2 | L4: 6 | M4: Yes | N4: Budget freeze reported by prospect
A5: E04 | B5: Olivia Hargreaves | C5: Enterprise | D5: 05-01-2024 | E5: Q1 2024 | F5: 175696.67 | G5: 163648.17 | H5: 673858.18 | I5: 174249.1 | J5: Qualify:25%,Propose:30%,Negotiate:35%,Close:10% | K5: 3 | L5: 3 | M5: Late | N5: NA
A6: E05 | B6: Richard Cavendish | C6: enterprise | D6: 05-01-2024 | E6: Jan-Mar 2024 | F6: 109537.6 | G6: 117300.04 | H6: 332070.5 | I6: 109714.81 | J6: Qualify:15%,Propose:40%,Negotiate:25%,Close:20% | K6: 6 | L6: 6 | M6: YES | N6: Revised following manager review
A7: E06 | B7: Helena Forsythe | C7: ENTERPRISE | D7: 05.01.2024 | E7: Q1 2024 | F7: 92727.32 | G7: 86008.17 | H7: £267,249 | I7: 79020.88 | J7: Qualify:20%,Propose:20%,Negotiate:40%,Close:20% | K7: 5 | L7: 2 | M7: Y
A8: M01 | B8: Daniel Ashworth | C8: Mid-Market | D8: 05/01/24 | E8: Jan-Mar 2024 | F8: 58658.74 | G8: 93144.86 | H8: 286520.93 | I8: 64403.07 | J8: Qualify:5%,Propose:45%,Negotiate:30%,Close:20% | K8: 5 | L8: 1 | M8: y
A9: M02 | B9: Priya Mehta | C9: MM | D9: 05/01/2024 | E9: Q1 2024 | F9: 65936.68 | G9: 65711.28 | H9: 317995.87 | I9: 102198.51 | J9: Qualify:15%,Propose:40%,Negotiate:25%,Close:20% | K9: 3 | L9: 2 | M9: yes
A10: M03 | B10: Tom Baxter | C10: MidMarket | D10: 05/01/2024 | E10: Q1 2024 | F10: 543030 | G10: 30943.06 | H10: 2325305 | I10: 68408.93 | J10: Qualify:15%,Propose:40%,Negotiate:25%,Close:20% | K10: 3 | L10: 4 | M10: y | N10: Verbal commit received – awaiting paperwork
A11: M04 | B11: Claire Pemberton | C11: MM | D11: 05.01.2024 | E11: Q1 2024 | F11: 81578.12 | G11: 71075.53 | H11: 260739.44 | I11: 70835.02 | J11: Qualify:25%,Propose:30%,Negotiate:35%,Close:10% | K11: 6 | L11: 4 | M11: n | N11: -
A12: M05 | B12: Nathan Griffiths | C12: MM | D12: 05.01.2024 | E12: Q1 2024 | F12: 81830.2 | G12: 70885.53 | H12: 216975.38 | I12: 68586.08 | J12: Qualify:5%,Propose:45%,Negotiate:30%,Close:20% | K12: 1 | L12: 2 | M12: yes
A13: M06 | B13: Yasmin Khalid | C13: mid-market | D13: 05 Jan 2024 | E13: Q1-2024 | F13: 69128.69 | G13: 69970.43 | H13: 340285.35 | I13: 110347.15 | J13: Qualify:10%,Propose:35%,Negotiate:40%,Close:15% | K13: 2 | L13: 1 | M13: Y | N13: Forecast includes upsell opportunity
A14: M07 | B14: Andrew Collinson | C14: Mid market | D14: 2024-01-05 | E14: Q1 2024 | F14: 87439.06 | G14: 100434.85 | H14: 252435.87 | I14: 87009.74 | J14: Qualify:30%,Propose:25%,Negotiate:25%,Close:20% | K14: 5 | L14: 8 | M14: Yes | N14: Verbal commit received – awaiting paperwork
A15: S01 | B15: Lucy Drummond | C15: SMB | D15: 05/01/2024 | E15: Q1 2024 | F15: 9850.08 | G15: 7722.27 | H15: 30417.13 | I15: 10078.68 | J15: Qualify:20%,Propose:20%,Negotiate:40%,Close:20% | K15: 5 | L15: 15 | M15: Yes | N15: n/a
A16: S02 | B16: Ben Hartley | C16: SMB | D16: 05/01/24 | E16: Q1 2024 | F16: 24852.66 | G16: 12914.1 | H16: 4330.13 | I16: 1193.85 | J16: Qualify:10%,Propose:35%,Negotiate:40%,Close:15% | K16: 3 | L16: 14 | M16: yes
A17: S03 | B17: Fiona McKenzie | C17: Smb | D17: 05/01/2024 | E17: Jan-Mar 2024 | F17: 24515.3 | G17: 30487.63 | H17: 93706.1 | I17: 25701.93 | J17: Qualify:20%,Propose:20%,Negotiate:40%,Close:20% | K17: 12 | L17: 12 | M17: yes | N17: Budget freeze reported by prospect
A18: S04 | B18: Callum Reid | C18: S M B | D18: 05/01/24 | E18: Q1 2024 | F18: 14780.27 | G18: 17796.63 | H18: 40361.18 | I18: 9163.43 | J18: Qualify:20%,Propose:20%,Negotiate:40%,Close:20% | K18: 2 | L18: 2 | M18: yes | N18: Revised following manager review
A19: S05 | B19: Amara Osei | C19: S M B | D19: 05-01-2024 | E19: Q1 2024 | F19: 30534.07 | G19: 31793.74 | H19: 3753.56 | I19: 1271.05 | J19: Qualify:20%,Propose:20%,Negotiate:40%,Close:20% | K19: 2 | L19: 4 | M19: no | N19: Revised following manager review
A20: S06 | B20: Steven Bowman | C20: Smb | D20: 05/01/2024 | E20: Q1 2024 | F20: 19860.67 | G20: 9686 | H20: 50882.36 | I20: 12032.23 | J20: Qualify:10%,Propose:35%,Negotiate:40%,Close:15% | K20: 8 | L20: 8 | M20: yes | N20: N/A
A21: S07 | B21: Rachel Sutton | C21: Smb | D21: 05 Jan 2024 | E21: Q1 2024 | F21: 29474.33 | G21: 25459.86 | H21: 122320k | I21: 27811.19 | J21: Qualify:15%,Propose:40%,Negotiate:25%,Close:20% | K21: 3 | L21: 2 | M21: NO
A22: E01 | B22: James Whitfield | C22: enterprise | D22: 12/01/24 | E22: Q1 2024 | F22: 117165.29 | G22: 109824.23 | H22: 394169.55 | I22: 100192.76 | J22: Qualify:20%,Propose:20%,Negotiate:40%,Close:20% | K22: 5 | L22: 7 | M22: y | N22: New logo opportunity added
A23: E02 | B23: Sarah Thornton | C23: ENTERPRISE | D23: 12/01/2024 | E23: Q1 2024 | F23: 68871.99 | G23: 111983.87 | H23: 296107.25 | I23: 68868.15 | J23: Qualify:30%,Propose:25%,Negotiate:25%,Close:20% | K23: 4 | L23: 2 | M23: YES | N23: Forecast includes upsell opportunity
A24: E03 | B24: Marcus Bellingham | C24: ENTERPRISE | D24: 12.01.2024 | E24: Q1-2024 | F24: 196721.52 | G24: 190548.4 | H24: 703224.44 | I24: 204849.25 | J24: Qualify:20%,Propose:35%,Negotiate:30%,Close:15% | K24: 4 | L24: 4 | M24: yes | N24: Deal pulled forward from next quarter
A25: E04 | B25: Olivia Hargreaves | C25: enterprise | D25: 12 Jan 2024 | E25: Q1 2024 | F25: 111449.69 | G25: 106084.59 | H25: £291,500 | I25: 82761.82 | J25: Qualify:5%,Propose:45%,Negotiate:30%,Close:20% | K25: 1 | L25: 1 | M25: y | N25: -
A26: E05 | B26: Richard Cavendish | C26: Enterprise | D26: 2024-01-12 | E26: q1 2024 | F26: 192575.38 | G26: 198611.83 | H26: 505615.51 | I26: 163929.23 | J26: Qualify:30%,Propose:25%,Negotiate:25%,Close:20% | K26: 4 | L26: 8 | M26: Y | N26: none
A27: E06 | B27: Helena Forsythe | C27: ENT | D27: 12.01.2024 | E27: Q1 2024 | F27: 184111.76 | G27: 183365.72 | H27: 806306.78 | I27: 183146.88 | J27: Qualify:15%,Propose:40%,Negotiate:25%,Close:20% | K27: 5 | L27: 5 | M27: yes | N27: Revised following manager review
A28: M01 | B28: Daniel Ashworth | C28: MM | D28: 12 Jan 2024 | E28: Q1 2024 | F28: 56849.47 | G28: 90344.27 | H28: 201215.05 | I28: 50590.37 | J28: Qualify:5%,Propose:45%,Negotiate:30%,Close:20% | K28: 5 | L28: 8 | M28: No | N28: -
A29: M02 | B29: Priya Mehta | C29: Mid market | D29: 12/01/2024 | E29: Q1-2024 | F29: 74078.04 | G29: 80742.14 | H29: 275612.82 | I29: 72364.66 | J29: Qualify:20%,Propose:20%,Negotiate:40%,Close:20% | K29: 4 | L29: 4 | M29: Y | N29: Pipeline updated post-QBR
A30: M03 | B30: Tom Baxter | C30: Mid Market | D30: 12/01/2024 | E30: Q1 2024 | F30: 73444.33 | G30: 38100.26 | H30: 222473.95 | I30: 68835.45 | J30: Qualify:20%,Propose:35%,Negotiate:30%,Close:15% | K30: 4 | L30: 6 | M30: Y | N30: Two deals slipped to next week
A31: M04 | B31: Claire Pemberton | C31: MidMarket | D31: 12/01/24 | E31: Q1-2024 | F31: 86976.7 | G31: 79132.12 | H31: 352546.08 | I31: 91840.15 | J31: Qualify:15%,Propose:40%,Negotiate:25%,Close:20% | K31: 1 | L31: 1 | M31: yes | N31: Forecast includes upsell opportunity
A32: M07 | B32: Andrew Collinson | C32: Mid market | D32: 12/01/2024 | E32: Jan-Mar 2024 | F32: 70640.84 | G32: 80350.55 | H32: 342867.77 | I32: 96228.12 | J32: Qualify:30%,Propose:25%,Negotiate:25%,Close:20% | K32: 6 | L32: 7 | M32: YES | N32: n/a
A33: S02 | B33: Ben Hartley | C33: Small Business | D33: 12.01.2024 | E33: Q1 2024 | F33: 28375.2 | G33: 16264.33 | H33: 121113.07 | I33: 36908.63 | J33: Qualify:20%,Propose:35%,Negotiate:30%,Close:15% | K33: 12 | L33: 9 | M33: y | N33: Budget freeze reported by prospect
A34: S03 | B34: Fiona McKenzie | C34: Smb | D34: 12/01/24 | E34: Q1 2024 | F34: 14584.31 | G34: 14326.96 | H34: 610823 | I34: 16059.35 | J34: Qualify:15%,Propose:40%,Negotiate:25%,Close:20% | K34: 7 | L34: 11 | M34: yes | N34: -
A35: S04 | B35: Callum Reid | C35: Smb | D35: 2024-01-12 | E35: Q1 2024 | F35: 28470.45 | G35: 31183.81 | H35: 121842.29 | I35: 22288.78 | J35: Qualify:20%,Propose:20%,Negotiate:40%,Close:20% | K35: 6 | L35: 12 | M35: yes | N35: none
A36: S05 | B36: Amara Osei | C36: Smb | D36: 12/01/24 | E36: Q1-2024 | F36: 14787.9 | G36: 11983.05 | H36: 48635.48 | I36: 16616.27 | J36: Qualify:15%,Propose:40%,Negotiate:25%,Close:20% | K36: 4 | L36: 5 | M36: Y | N36: Budget freeze reported by prospect
A37: S07 | B37: Rachel Sutton | C37: Small Business | D37: 2024-01-12 | E37: Q1 2024 | F37: 15887.69 | G37: 19415.47 | H37: 74213.83 | I37: 24369.03 | J37: Qualify:10%,Propose:35%,Negotiate:40%,Close:15% | K37: 11 | L37: 12 | M37: Y
A38: E01 | B38: James Whitfield | C38: ENTERPRISE | D38: 19-01-2024 | E38: q1 2024 | F38: 168122.4 | G38: 156114.67 | H38: 761233.88 | I38: 148045.34 | J38: Qualify:25%,Propose:30%,Negotiate:35%,Close:10% | K38: 2 | L38: 3 | M38: Y
A39: E02 | B39: Sarah Thornton | C39: Ent | D39: 19.01.2024 | E39: Q1 2024 | F39: 116610.42 | G39: 203571.6 | H39: 368677.28 | I39: 81395.49 | J39: Qualify:5%,Propose:45%,Negotiate:30%,Close:20% | K39: 5 | L39: 4 | M39: Yes | N39: none
A40: E03 | B40: Marcus Bellingham | C40: Enterprise | D40: 19/01/2024 | E40: Jan-Mar 2024 | F40: 112679.33 | G40: 108434.56 | H40: 401459.27 | I40: 116462.49 | J40: Qualify:20%,Propose:20%,Negotiate:40%,Close:20% | K40: 3 | L40: 4 | M40: Yes | N40: Forecast includes upsell opportunity
...

Sheet Cleaned_Forecast_Data
A1: Rep_ID | B1: Rep_Name | C1: Segment | D1: Week_Ending_Date | E1: Quarter | F1: Forecasted_Revenue | G1: Actual_Revenue_Closed | H1: Pipeline_Value | I1: Weighted_Pipeline | J1: Deal_Count_Forecasted | K1: Deal_Count_Closed | L1: Forecast_Submitted_On_Time | M1: Notes_Clean2 | N1: Low_Pipeline_Flag
A2: E01 | B2: James Whitfield | C2: Enterprise | D2: 45296 | E2: Q1 2024 | F2: 83501.51 | G2: 80495.84 | H2: 237882.83 | I2: 72771.57 | J2: 5 | K2: 4 | L2: Yes | N2: OK
A3: E02 | B3: Sarah Thornton | C3: Enterprise | D3: 45296 | E3: Q1 2024 | F3: 101890.04 | G3: 187730.93 | H3: 432558.75 | I3: 89293.76 | J3: 3 | K3: 3 | L3: Yes | M3: Verbal commit received – awaiting paperwork | N3: OK
A4: E03 | B4: Marcus Bellingham | C4: Enterprise | D4: 45296 | E4: Q1 2024 | F4: 196116.65 | G4: 199835.64 | H4: 773362.56 | I4: 145229.87 | J4: 2 | K4: 6 | L4: Yes | M4: Budget freeze reported by prospect | N4: OK
A5: E04 | B5: Olivia Hargreaves | C5: Enterprise | D5: 45296 | E5: Q1 2024 | F5: 175696.67 | G5: 163648.17 | H5: 673858.18 | I5: 174249.1 | J5: 3 | K5: 3 | L5: No | N5: OK
A6: E05 | B6: Richard Cavendish | C6: Enterprise | D6: 45296 | E6: Q1 2024 | F6: 109537.6 | G6: 117300.04 | H6: 332070.5 | I6: 109714.81 | J6: 6 | K6: 6 | L6: Yes | M6: Revised following manager review | N6: OK
A7: E06 | B7: Helena Forsythe | C7: Enterprise | D7: 45296 | E7: Q1 2024 | F7: 92727.32 | G7: 86008.17 | H7: 267249 | I7: 79020.88 | J7: 5 | K7: 2 | L7: Yes | N7: OK
A8: M01 | B8: Daniel Ashworth | C8: Mid-Market | D8: 45296 | E8: Q1 2024 | F8: 58658.74 | G8: 93144.86 | H8: 286520.93 | I8: 64403.07 | J8: 5 | K8: 1 | L8: Yes | N8: OK
A9: M02 | B9: Priya Mehta | C9: Mid-Market | D9: 45296 | E9: Q1 2024 | F9: 65936.68 | G9: 65711.28 | H9: 317995.87 | I9: 102198.51 | J9: 3 | K9: 2 | L9: Yes | N9: OK
A10: M03 | B10: Tom Baxter | C10: Mid-Market | D10: 45296 | E10: Q1 2024 | F10: 543030 | G10: 30943.06 | H10: 2325305 | I10: 68408.93 | J10: 3 | K10: 4 | L10: Yes | M10: Verbal commit received – awaiting paperwork | N10: OK
A11: M04 | B11: Claire Pemberton | C11: Mid-Market | D11: 45296 | E11: Q1 2024 | F11: 81578.12 | G11: 71075.53 | H11: 260739.44 | I11: 70835.02 | J11: 6 | K11: 4 | L11: No | N11: OK
A12: M05 | B12: Nathan Griffiths | C12: Mid-Market | D12: 45296 | E12: Q1 2024 | F12: 81830.2 | G12: 70885.53 | H12: 216975.38 | I12: 68586.08 | J12: 1 | K12: 2 | L12: Yes | N12: OK
A13: M06 | B13: Yasmin Khalid | C13: Mid-Market | D13: 45296 | E13: Q1 2024 | F13: 69128.69 | G13: 69970.43 | H13: 340285.35 | I13: 110347.15 | J13: 2 | K13: 1 | L13: Yes | M13: Forecast includes upsell opportunity | N13: OK
A14: M07 | B14: Andrew Collinson | C14: Mid-Market | D14: 45296 | E14: Q1 2024 | F14: 87439.06 | G14: 100434.85 | H14: 252435.87 | I14: 87009.74 | J14: 5 | K14: 8 | L14: Yes | M14: Verbal commit received – awaiting paperwork | N14: OK
A15: S01 | B15: Lucy Drummond | C15: SMB | D15: 45296 | E15: Q1 2024 | F15: 9850.08 | G15: 7722.27 | H15: 30417.13 | I15: 10078.68 | J15: 5 | K15: 15 | L15: Yes | N15: OK
A16: S02 | B16: Ben Hartley | C16: SMB | D16: 45296 | E16: Q1 2024 | F16: 24852.66 | G16: 12914.1 | H16: 4330.13 | I16: 1193.85 | J16: 3 | K16: 14 | L16: Yes | N16: FLAG
A17: S03 | B17: Fiona McKenzie | C17: SMB | D17: 45296 | E17: Q1 2024 | F17: 24515.3 | G17: 30487.63 | H17: 93706.1 | I17: 25701.93 | J17: 12 | K17: 12 | L17: Yes | M17: Budget freeze reported by prospect | N17: OK
A18: S04 | B18: Callum Reid | C18: SMB | D18: 45296 | E18: Q1 2024 | F18: 14780.27 | G18: 17796.63 | H18: 40361.18 | I18: 9163.43 | J18: 2 | K18: 2 | L18: Yes | M18: Revised following manager review | N18: OK
A19: S05 | B19: Amara Osei | C19: SMB | D19: 45296 | E19: Q1 2024 | F19: 30534.07 | G19: 31793.74 | H19: 3753.56 | I19: 1271.05 | J19: 2 | K19: 4 | L19: No | M19: Revised following manager review | N19: FLAG
A20: S06 | B20: Steven Bowman | C20: SMB | D20: 45296 | E20: Q1 2024 | F20: 19860.67 | G20: 9686 | H20: 50882.36 | I20: 12032.23 | J20: 8 | K20: 8 | L20: Yes | N20: OK
A21: S07 | B21: Rachel Sutton | C21: SMB | D21: 45296 | E21: Q1 2024 | F21: 29474.33 | G21: 25459.86 | H21: 122320 | I21: 27811.19 | J21: 3 | K21: 2 | L21: No | N21: OK
A22: E01 | B22: James Whitfield | C22: Enterprise | D22: 45303 | E22: Q1 2024 | F22: 117165.29 | G22: 109824.23 | H22: 394169.55 | I22: 100192.76 | J22: 5 | K22: 7 | L22: Yes | M22: New logo opportunity added | N22: OK
A23: E02 | B23: Sarah Thornton | C23: Enterprise | D23: 45303 | E23: Q1 2024 | F23: 68871.99 | G23: 111983.87 | H23: 296107.25 | I23: 68868.15 | J23: 4 | K23: 2 | L23: Yes | M23: Forecast includes upsell opportunity | N23: OK
A24: E03 | B24: Marcus Bellingham | C24: Enterprise | D24: 45303 | E24: Q1 2024 | F24: 196721.52 | G24: 190548.4 | H24: 703224.44 | I24: 204849.25 | J24: 4 | K24: 4 | L24: Yes | M24: Deal pulled forward from next quarter | N24: OK
A25: E04 | B25: Olivia Hargreaves | C25: Enterprise | D25: 45303 | E25: Q1 2024 | F25: 111449.69 | G25: 106084.59 | H25: 291500 | I25: 82761.82 | J25: 1 | K25: 1 | L25: Yes | N25: OK
A26: E05 | B26: Richard Cavendish | C26: Enterprise | D26: 45303 | E26: Q1 2024 | F26: 192575.38 | G26: 198611.83 | H26: 505615.51 | I26: 163929.23 | J26: 4 | K26: 8 | L26: Yes | N26: OK
A27: E06 | B27: Helena Forsythe | C27: Enterprise | D27: 45303 | E27: Q1 2024 | F27: 184111.76 | G27: 183365.72 | H27: 806306.78 | I27: 183146.88 | J27: 5 | K27: 5 | L27: Yes | M27: Revised following manager review | N27: OK
A28: M01 | B28: Daniel Ashworth | C28: Mid-Market | D28: 45303 | E28: Q1 2024 | F28: 56849.47 | G28: 90344.27 | H28: 201215.05 | I28: 50590.37 | J28: 5 | K28: 8 | L28: No | N28: OK
A29: M02 | B29: Priya Mehta | C29: Mid-Market | D29: 45303 | E29: Q1 2024 | F29: 74078.04 | G29: 80742.14 | H29: 275612.82 | I29: 72364.66 | J29: 4 | K29: 4 | L29: Yes | M29: Pipeline updated post-QBR | N29: OK
A30: M03 | B30: Tom Baxter | C30: Mid-Market | D30: 45303 | E30: Q1 2024 | F30: 73444.33 | G30: 38100.26 | H30: 222473.95 | I30: 68835.45 | J30: 4 | K30: 6 | L30: Yes | M30: Two deals slipped to next week | N30: OK
A31: M04 | B31: Claire Pemberton | C31: Mid-Market | D31: 45303 | E31: Q1 2024 | F31: 86976.7 | G31: 79132.12 | H31: 352546.08 | I31: 91840.15 | J31: 1 | K31: 1 | L31: Yes | M31: Forecast includes upsell opportunity | N31: OK
A32: M07 | B32: Andrew Collinson | C32: Mid-Market | D32: 45303 | E32: Q1 2024 | F32: 70640.84 | G32: 80350.55 | H32: 342867.77 | I32: 96228.12 | J32: 6 | K32: 7 | L32: Yes | N32: OK
A33: S02 | B33: Ben Hartley | C33: SMB | D33: 45303 | E33: Q1 2024 | F33: 28375.2 | G33: 16264.33 | H33: 121113.07 | I33: 36908.63 | J33: 12 | K33: 9 | L33: Yes | M33: Budget freeze reported by prospect | N33: OK
A34: S03 | B34: Fiona McKenzie | C34: SMB | D34: 45303 | E34: Q1 2024 | F34: 14584.31 | G34: 14326.96 | H34: 610823 | I34: 16059.35 | J34: 7 | K34: 11 | L34: Yes | N34: OK
A35: S04 | B35: Callum Reid | C35: SMB | D35: 45303 | E35: Q1 2024 | F35: 28470.45 | G35: 31183.81 | H35: 121842.29 | I35: 22288.78 | J35: 6 | K35: 12 | L35: Yes | N35: OK
A36: S05 | B36: Amara Osei | C36: SMB | D36: 45303 | E36: Q1 2024 | F36: 14787.9 | G36: 11983.05 | H36: 48635.48 | I36: 16616.27 | J36: 4 | K36: 5 | L36: Yes | M36: Budget freeze reported by prospect | N36: OK
A37: S07 | B37: Rachel Sutton | C37: SMB | D37: 45303 | E37: Q1 2024 | F37: 15887.69 | G37: 19415.47 | H37: 74213.83 | I37: 24369.03 | J37: 11 | K37: 12 | L37: Yes | N37: OK
A38: E01 | B38: James Whitfield | C38: Enterprise | D38: 45310 | E38: Q1 2024 | F38: 168122.4 | G38: 156114.67 | H38: 761233.88 | I38: 148045.34 | J38: 2 | K38: 3 | L38: Yes | N38: OK
A39: E02 | B39: Sarah Thornton | C39: Enterprise | D39: 45310 | E39: Q1 2024 | F39: 116610.42 | G39: 203571.6 | H39: 368677.28 | I39: 81395.49 | J39: 5 | K39: 4 | L39: Yes | N39: OK
A40: E03 | B40: Marcus Bellingham | C40: Enterprise | D40: 45310 | E40: Q1 2024 | F40: 112679.33 | G40: 108434.56 | H40: 401459.27 | I40: 116462.49 | J40: 3 | K40: 4 | L40: Yes | M40: Forecast includes upsell opportunity | N40: OK
...

Sheet Email_Summary
A1: Mertics | B1: Value
A2: Forecast_Accuracy_Pct | B2: =1-ABS(SUMIFS(Cleaned_Forecast_Data!F:F,Cleaned_Forecast_Data!E:E,"<>Q4 2024")-SUMIFS(Cleaned_Forecast_Data!G:G,Cleaned_Forecast_Data!E:E,"<>Q4 2024"))/SUMIFS(Cleaned_Forecast_Data!G:G,Cleaned_Forecast_Data!E:E,"<>Q4 2024") -> 0.4094198
A3: Total_Forecasted | B3: =SUMIFS(Cleaned_Forecast_Data!F:F,Cleaned_Forecast_Data!E:E,"<>Q4 2024") -> 73712330
A4: Total_Actual | B4: =SUMIFS(Cleaned_Forecast_Data!G:G,Cleaned_Forecast_Data!E:E,"<>Q4 2024") -> 46343045
A5: Miss_Amount | B5: =B3-B4 -> 27369285
A6: Weakest_Segment | B6: SMB
A7: Strongest_Segment | B7: Enterprise
A8: Q3_Miss_Amount | B8: =SUMIFS(Cleaned_Forecast_Data!F:F,Cleaned_Forecast_Data!E:E,"Q3 2024")-SUMIFS(Cleaned_Forecast_Data!G:G,Cleaned_Forecast_Data!E:E,"Q3 2024") -> 16616195

Sheet Analysis_Sheet
A1: Section - 1 Forecast Accuracy Summary by Rep (Q1 to Q3 2024 only — Q4 excluded as quarter not yet closed)
A3: Rep_ID | B3: Rep_Name | C3: Segment | D3: Total_Forecasted | E3: Total_Actual | F3: Forecast_Accuracy_Pct | G3: Bias | H3: Total Submissions | I3: On Time %
A4: E01 | B4: James Whitfield | C4: Enterprise | D4: =SUMIFS(RAW_Forecast_Data!F:F,RAW_Forecast_Data!A:A,A4,RAW_Forecast_Data!E:E,"<>Q4 2024") -> 19225747 | E4: =SUMIFS(RAW_Forecast_Data!G:G,RAW_Forecast_Data!A:A,A4,RAW_Forecast_Data!E:E,"<>Q4 2024") -> 4793418.1 | F4: =IFERROR(1-ABS(D4-E4)/E4,"") -> -2.0108637 | G4: =IF(D4>E4,"Over-Forecaster","Under-Forecaster") -> Over-Forecaster | H4: =COUNTIF(RAW_Forecast_Data!A:A,A4) -> 50 | I4: =IFERROR(COUNTIFS(RAW_Forecast_Data!A:A,A4,RAW_Forecast_Data!M:M,"Yes")/H4,"") -> 0.46
A5: E02 | B5: Sarah Thornton | C5: Enterprise | D5: =SUMIFS(RAW_Forecast_Data!F:F,RAW_Forecast_Data!A:A,A5,RAW_Forecast_Data!E:E,"<>Q4 2024") -> 4452816.2 | E5: =SUMIFS(RAW_Forecast_Data!G:G,RAW_Forecast_Data!A:A,A5,RAW_Forecast_Data!E:E,"<>Q4 2024") -> 5916007.8 | F5: =IFERROR(1-ABS(D5-E5)/E5,"") -> 0.75267248 | G5: =IF(D5>E5,"Over-Forecaster","Under-Forecaster") -> Under-Forecaster | H5: =COUNTIF(RAW_Forecast_Data!A:A,A5) -> 51 | I5: =IFERROR(COUNTIFS(RAW_Forecast_Data!A:A,A5,RAW_Forecast_Data!M:M,"Yes")/H5,"") -> 0.50980392
A6: E03 | B6: Marcus Bellingham | C6: Enterprise | D6: =SUMIFS(RAW_Forecast_Data!F:F,RAW_Forecast_Data!A:A,A6,RAW_Forecast_Data!E:E,"<>Q4 2024") -> 5471677 | E6: =SUMIFS(RAW_Forecast_Data!G:G,RAW_Forecast_Data!A:A,A6,RAW_Forecast_Data!E:E,"<>Q4 2024") -> 4481642.6 | F6: =IFERROR(1-ABS(D6-E6)/E6,"") -> 0.77909116 | G6: =IF(D6>E6,"Over-Forecaster","Under-Forecaster") -> Over-Forecaster | H6: =COUNTIF(RAW_Forecast_Data!A:A,A6) -> 50 | I6: =IFERROR(COUNTIFS(RAW_Forecast_Data!A:A,A6,RAW_Forecast_Data!M:M,"Yes")/H6,"") -> 0.48
A7: E04 | B7: Olivia Hargreaves | C7: Enterprise | D7: =SUMIFS(RAW_Forecast_Data!F:F,RAW_Forecast_Data!A:A,A7,RAW_Forecast_Data!E:E,"<>Q4 2024") -> 5680832.5 | E7: =SUMIFS(RAW_Forecast_Data!G:G,RAW_Forecast_Data!A:A,A7,RAW_Forecast_Data!E:E,"<>Q4 2024") -> 5029247.9 | F7: =IFERROR(1-ABS(D7-E7)/E7,"") -> 0.87044094 | G7: =IF(D7>E7,"Over-Forecaster","Under-Forecaster") -> Over-Forecaster | H7: =COUNTIF(RAW_Forecast_Data!A:A,A7) -> 51 | I7: =IFERROR(COUNTIFS(RAW_Forecast_Data!A:A,A7,RAW_Forecast_Data!M:M,"Yes")/H7,"") -> 0.54901961
A8: E05 | B8: Richard Cavendish | C8: Enterprise | D8: =SUMIFS(RAW_Forecast_Data!F:F,RAW_Forecast_Data!A:A,A8,RAW_Forecast_Data!E:E,"<>Q4 2024") -> 6035497.9 | E8: =SUMIFS(RAW_Forecast_Data!G:G,RAW_Forecast_Data!A:A,A8,RAW_Forecast_Data!E:E,"<>Q4 2024") -> 4989297.1 | F8: =IFERROR(1-ABS(D8-E8)/E8,"") -> 0.79031098 | G8: =IF(D8>E8,"Over-Forecaster","Under-Forecaster") -> Over-Forecaster | H8: =COUNTIF(RAW_Forecast_Data!A:A,A8) -> 50 | I8: =IFERROR(COUNTIFS(RAW_Forecast_Data!A:A,A8,RAW_Forecast_Data!M:M,"Yes")/H8,"") -> 0.6
A9: E06 | B9: Helena Forsythe | C9: Enterprise | D9: =SUMIFS(RAW_Forecast_Data!F:F,RAW_Forecast_Data!A:A,A9,RAW_Forecast_Data!E:E,"<>Q4 2024") -> 6824711.6 | E9: =SUMIFS(RAW_Forecast_Data!G:G,RAW_Forecast_Data!A:A,A9,RAW_Forecast_Data!E:E,"<>Q4 2024") -> 4227008.8 | F9: =IFERROR(1-ABS(D9-E9)/E9,"") -> 0.38545127 | G9: =IF(D9>E9,"Over-Forecaster","Under-Forecaster") -> Over-Forecaster | H9: =COUNTIF(RAW_Forecast_Data!A:A,A9) -> 47 | I9: =IFERROR(COUNTIFS(RAW_Forecast_Data!A:A,A9,RAW_Forecast_Data!M:M,"Yes")/H9,"") -> 0.55319149
A10: M01 | B10: Daniel Ashworth | C10: Mid-Market | D10: =SUMIFS(RAW_Forecast_Data!F:F,RAW_Forecast_Data!A:A,A10,RAW_Forecast_Data!E:E,"<>Q4 2024") -> 1767849.6 | E10: =SUMIFS(RAW_Forecast_Data!G:G,RAW_Forecast_Data!A:A,A10,RAW_Forecast_Data!E:E,"<>Q4 2024") -> 2305549.9 | F10: =IFERROR(1-ABS(D10-E10)/E10,"") -> 0.76678001 | G10: =IF(D10>E10,"Over-Forecaster","Under-Forecaster") -> Under-Forecaster | H10: =COUNTIF(RAW_Forecast_Data!A:A,A10) -> 50 | I10: =IFERROR(COUNTIFS(RAW_Forecast_Data!A:A,A10,RAW_Forecast_Data!M:M,"Yes")/H10,"") -> 0.56
A11: M02 | B11: Priya Mehta | C11: Mid-Market | D11: =SUMIFS(RAW_Forecast_Data!F:F,RAW_Forecast_Data!A:A,A11,RAW_Forecast_Data!E:E,"<>Q4 2024") -> 2867670.5 | E11: =SUMIFS(RAW_Forecast_Data!G:G,RAW_Forecast_Data!A:A,A11,RAW_Forecast_Data!E:E,"<>Q4 2024") -> 1945103.2 | F11: =IFERROR(1-ABS(D11-E11)/E11,"") -> 0.52569755 | G11: =IF(D11>E11,"Over-Forecaster","Under-Forecaster") -> Over-Forecaster | H11: =COUNTIF(RAW_Forecast_Data!A:A,A11) -> 49 | I11: =IFERROR(COUNTIFS(RAW_Forecast_Data!A:A,A11,RAW_Forecast_Data!M:M,"Yes")/H11,"") -> 0.44897959
A12: M03 | B12: Tom Baxter | C12: Mid-Market | D12: =SUMIFS(RAW_Forecast_Data!F:F,RAW_Forecast_Data!A:A,A12,RAW_Forecast_Data!E:E,"<>Q4 2024") -> 4555593.9 | E12: =SUMIFS(RAW_Forecast_Data!G:G,RAW_Forecast_Data!A:A,A12,RAW_Forecast_Data!E:E,"<>Q4 2024") -> 1377349.9 | F12: =IFERROR(1-ABS(D12-E12)/E12,"") -> -1.3075067 | G12: =IF(D12>E12,"Over-Forecaster","Under-Forecaster") -> Over-Forecaster | H12: =COUNTIF(RAW_Forecast_Data!A:A,A12) -> 49 | I12: =IFERROR(COUNTIFS(RAW_Forecast_Data!A:A,A12,RAW_Forecast_Data!M:M,"Yes")/H12,"") -> 0.40816327
A13: M04 | B13: Claire Pemberton | C13: Mid-Market | D13: =SUMIFS(RAW_Forecast_Data!F:F,RAW_Forecast_Data!A:A,A13,RAW_Forecast_Data!E:E,"<>Q4 2024") -> 2626574.5 | E13: =SUMIFS(RAW_Forecast_Data!G:G,RAW_Forecast_Data!A:A,A13,RAW_Forecast_Data!E:E,"<>Q4 2024") -> 1699234.6 | F13: =IFERROR(1-ABS(D13-E13)/E13,"") -> 0.45426025 | G13: =IF(D13>E13,"Over-Forecaster","Under-Forecaster") -> Over-Forecaster | H13: =COUNTIF(RAW_Forecast_Data!A:A,A13) -> 51 | I13: =IFERROR(COUNTIFS(RAW_Forecast_Data!A:A,A13,RAW_Forecast_Data!M:M,"Yes")/H13,"") -> 0.45098039
A14: M05 | B14: Nathan Griffiths | C14: Mid-Market | D14: =SUMIFS(RAW_Forecast_Data!F:F,RAW_Forecast_Data!A:A,A14,RAW_Forecast_Data!E:E,"<>Q4 2024") -> 2681890.6 | E14: =SUMIFS(RAW_Forecast_Data!G:G,RAW_Forecast_Data!A:A,A14,RAW_Forecast_Data!E:E,"<>Q4 2024") -> 1451053.5 | F14: =IFERROR(1-ABS(D14-E14)/E14,"") -> 0.15176309 | G14: =IF(D14>E14,"Over-Forecaster","Under-Forecaster") -> Over-Forecaster | H14: =COUNTIF(RAW_Forecast_Data!A:A,A14) -> 40 | I14: =IFERROR(COUNTIFS(RAW_Forecast_Data!A:A,A14,RAW_Forecast_Data!M:M,"Yes")/H14,"") -> 0.55
A15: M06 | B15: Yasmin Khalid | C15: Mid-Market | D15: =SUMIFS(RAW_Forecast_Data!F:F,RAW_Forecast_Data!A:A,A15,RAW_Forecast_Data!E:E,"<>Q4 2024") -> 3696704.6 | E15: =SUMIFS(RAW_Forecast_Data!G:G,RAW_Forecast_Data!A:A,A15,RAW_Forecast_Data!E:E,"<>Q4 2024") -> 1792911.8 | F15: =IFERROR(1-ABS(D15-E15)/E15,"") -> -0.061844056 | G15: =IF(D15>E15,"Over-Forecaster","Under-Forecaster") -> Over-Forecaster | H15: =COUNTIF(RAW_Forecast_Data!A:A,A15) -> 47 | I15: =IFERROR(COUNTIFS(RAW_Forecast_Data!A:A,A15,RAW_Forecast_Data!M:M,"Yes")/H15,"") -> 0.31914894
... A17: S01 | B17: Lucy Drummond | C17: SMB | D17: =SUMIFS(RAW_Forecast_Data!F:F,RAW_Forecast_Data!A:A,A17,RAW_Forecast_Data!E:E,"<>Q4 2024") -> 977364.28 | E17: =SUMIFS(RAW_Forecast_Data!G:G,RAW_Forecast_Data!A:A,A17,RAW_Forecast_Data!E:E,"<>Q4 2024") -> 662577.24 | F17: =IFERROR(1-ABS(D17-E17)/E17,"") -> 0.52490514 | G17: =IF(D17>E17,"Over-Forecaster","Under-Forecaster") -> Over-Forecaster | H17: =COUNTIF(RAW_Forecast_Data!A:A,A17) -> 47 | I17: =IFERROR(COUNTIFS(RAW_Forecast_Data!A:A,A17,RAW_Forecast_Data!M:M,"Yes")/H17,"") -> 0.5106383
A18: S02 | B18: Ben Hartley | C18: SMB | D18: =SUMIFS(RAW_Forecast_Data!F:F,RAW_Forecast_Data!A:A,A18,RAW_Forecast_Data!E:E,"<>Q4 2024") -> 1426472 | E18: =SUMIFS(RAW_Forecast_Data!G:G,RAW_Forecast_Data!A:A,A18,RAW_Forecast_Data!E:E,"<>Q4 2024") -> 575113.43 | F18: =IFERROR(1-ABS(D18-E18)/E18,"") -> -0.48033165 | G18: =IF(D18>E18,"Over-Forecaster","Under-Forecaster") -> Over-Forecaster | H18: =COUNTIF(RAW_Forecast_Data!A:A,A18) -> 52 | I18: =IFERROR(COUNTIFS(RAW_Forecast_Data!A:A,A18,RAW_Forecast_Data!M:M,"Yes")/H18,"") -> 0.51923077 | L18: =IFERROR(K16/K17,"")
A19: S03 | B19: Fiona McKenzie | C19: SMB | D19: =SUMIFS(RAW_Forecast_Data!F:F,RAW_Forecast_Data!A:A,A19,RAW_Forecast_Data!E:E,"<>Q4 2024") -> 991403.39 | E19: =SUMIFS(RAW_Forecast_Data!G:G,RAW_Forecast_Data!A:A,A19,RAW_Forecast_Data!E:E,"<>Q4 2024") -> 627810.16 | F19: =IFERROR(1-ABS(D19-E19)/E19,"") -> 0.42085482 | G19: =IF(D19>E19,"Over-Forecaster","Under-Forecaster") -> Over-Forecaster | H19: =COUNTIF(RAW_Forecast_Data!A:A,A19) -> 50 | I19: =IFERROR(COUNTIFS(RAW_Forecast_Data!A:A,A19,RAW_Forecast_Data!M:M,"Yes")/H19,"") -> 0.34
A20: S04 | B20: Callum Reid | C20: SMB | D20: =SUMIFS(RAW_Forecast_Data!F:F,RAW_Forecast_Data!A:A,A20,RAW_Forecast_Data!E:E,"<>Q4 2024") -> 679077.26 | E20: =SUMIFS(RAW_Forecast_Data!G:G,RAW_Forecast_Data!A:A,A20,RAW_Forecast_Data!E:E,"<>Q4 2024") -> 574019.08 | F20: =IFERROR(1-ABS(D20-E20)/E20,"") -> 0.8169779 | G20: =IF(D20>E20,"Over-Forecaster","Under-Forecaster") -> Over-Forecaster | H20: =COUNTIF(RAW_Forecast_Data!A:A,A20) -> 44 | I20: =IFERROR(COUNTIFS(RAW_Forecast_Data!A:A,A20,RAW_Forecast_Data!M:M,"Yes")/H20,"") -> 0.5
A21: S05 | B21: Amara Osei | C21: SMB | D21: =SUMIFS(RAW_Forecast_Data!F:F,RAW_Forecast_Data!A:A,A21,RAW_Forecast_Data!E:E,"<>Q4 2024") -> 1413894.9 | E21: =SUMIFS(RAW_Forecast_Data!G:G,RAW_Forecast_Data!A:A,A21,RAW_Forecast_Data!E:E,"<>Q4 2024") -> 654103.04 | F21: =IFERROR(1-ABS(D21-E21)/E21,"") -> -0.1615782 | G21: =IF(D21>E21,"Over-Forecaster","Under-Forecaster") -> Over-Forecaster | H21: =COUNTIF(RAW_Forecast_Data!A:A,A21) -> 49 | I21: =IFERROR(COUNTIFS(RAW_Forecast_Data!A:A,A21,RAW_Forecast_Data!M:M,"Yes")/H21,"") -> 0.42857143
A22: S06 | B22: Steven Bowman | C22: SMB | D22: =SUMIFS(RAW_Forecast_Data!F:F,RAW_Forecast_Data!A:A,A22,RAW_Forecast_Data!E:E,"<>Q4 2024") -> 1038726.4 | E22: =SUMIFS(RAW_Forecast_Data!G:G,RAW_Forecast_Data!A:A,A22,RAW_Forecast_Data!E:E,"<>Q4 2024") -> 524709.31 | F22: =IFERROR(1-ABS(D22-E22)/E22,"") -> 0.020377435 | G22: =IF(D22>E22,"Over-Forecaster","Under-Forecaster") -> Over-Forecaster | H22: =COUNTIF(RAW_Forecast_Data!A:A,A22) -> 46 | I22: =IFERROR(COUNTIFS(RAW_Forecast_Data!A:A,A22,RAW_Forecast_Data!M:M,"Yes")/H22,"") -> 0.54347826
A23: S07 | B23: Rachel Sutton | C23: SMB | D23: =SUMIFS(RAW_Forecast_Data!F:F,RAW_Forecast_Data!A:A,A23,RAW_Forecast_Data!E:E,"<>Q4 2024") -> 876338.27 | E23: =SUMIFS(RAW_Forecast_Data!G:G,RAW_Forecast_Data!A:A,A23,RAW_Forecast_Data!E:E,"<>Q4 2024") -> 745038.42 | F23: =IFERROR(1-ABS(D23-E23)/E23,"") -> 0.82376768 | G23: =IF(D23>E23,"Over-Forecaster","Under-Forecaster") -> Over-Forecaster | H23: =COUNTIF(RAW_Forecast_Data!A:A,A23) -> 50 | I23: =IFERROR(COUNTIFS(RAW_Forecast_Data!A:A,A23,RAW_Forecast_Data!M:M,"Yes")/H23,"") -> 0.56
A28: SECTION 2 - SEGMENT FORECAST ACCURACY SUMMARY (Q1 to Q3 2024 only)
A29: Segment | B29: Total Forecasted £ | C29: Total Actual Closed £ | D29: Forecast Accuracy % | E29: Average Error %
A30: Enterprise | B30: =SUMIFS(RAW_Forecast_Data!F:F,RAW_Forecast_Data!C:C,A30,RAW_Forecast_Data!E:E,"<>Q4 2024") -> 14380593 | C30: =SUMIFS(RAW_Forecast_Data!G:G,RAW_Forecast_Data!C:C,A30,RAW_Forecast_Data!E:E,"<>Q4 2024") -> 13078342 | D30: =IFERROR(1-ABS(B30-C30)/C30,"") -> 0.90042686 | E30: =IFERROR(ABS(B30-C30)/C30,"") -> 0.099573137
A31: Mid-Market | B31: =SUMIFS(RAW_Forecast_Data!F:F,RAW_Forecast_Data!C:C,A31,RAW_Forecast_Data!E:E,"<>Q4 2024") -> 7907622.5 | C31: =SUMIFS(RAW_Forecast_Data!G:G,RAW_Forecast_Data!C:C,A31,RAW_Forecast_Data!E:E,"<>Q4 2024") -> 3844083.1 | D31: =IFERROR(1-ABS(B31-C31)/C31,"") -> -0.057089374 | E31: =IFERROR(ABS(B31-C31)/C31,"") -> 1.0570894
A32: SMB | B32: =SUMIFS(RAW_Forecast_Data!F:F,RAW_Forecast_Data!C:C,A32,RAW_Forecast_Data!E:E,"<>Q4 2024") -> 3602747.2 | C32: =SUMIFS(RAW_Forecast_Data!G:G,RAW_Forecast_Data!C:C,A32,RAW_Forecast_Data!E:E,"<>Q4 2024") -> 2414286 | D32: =IFERROR(1-ABS(B32-C32)/C32,"") -> 0.50773806 | E32: =IFERROR(ABS(B32-C32)/C32,"") -> 0.49226194
A35: SECTION 3 — QUARTERLY FORECAST ACCURACY SUMMARY
A36: Q4 2024 excluded from accuracy calculation — actual revenue not available as quarter had not closed at time of data export
A37: Quarter | B37: Total Forecasted £ | C37: Total Actual Closed £ | D37: Forecast Accuracy % | E37: Miss Amount £
A38: Q1 2024 | B38: =SUMIFS(RAW_Forecast_Data!F:F,RAW_Forecast_Data!E:E,A38) -> 16813211 | C38: =SUMIFS(RAW_Forecast_Data!G:G,RAW_Forecast_Data!E:E,A38) -> 15230712 | D38: =IFERROR(1-ABS(B38-C38)/C38,"") -> 0.89609814 | E38: =IFERROR(B38-C38,"") -> 1582499.3
A39: Q2 2024 | B39: =SUMIFS(RAW_Forecast_Data!F:F,RAW_Forecast_Data!E:E,A39) -> 24730557 | C39: =SUMIFS(RAW_Forecast_Data!G:G,RAW_Forecast_Data!E:E,A39) -> 16561149 | D39: =IFERROR(1-ABS(B39-C39)/C39,"") -> 0.5067125 | E39: =IFERROR(B39-C39,"") -> 8169407.7
A40: Q3 2024 | B40: =SUMIFS(RAW_Forecast_Data!F:F,RAW_Forecast_Data!E:E,A40) -> 17691460 | C40: =SUMIFS(RAW_Forecast_Data!G:G,RAW_Forecast_Data!E:E,A40) -> 8377362.4 | D40: =IFERROR(1-ABS(B40-C40)/C40,"") -> -0.11181747 | E40: =IFERROR(B40-C40,"") -> 9314097.9
A43: SECTION 4 — PIPELINE SUPPORT ANALYSIS
A44: Total rows flagged | B44: =COUNTIF(Cleaned_Forecast_Data!N:N,"FLAG") -> 76
A45: Total rows in dataset | B45: 1048575
A46: Percentage of rows with no pipeline support | B46: =IFERROR(B44/B45,"") -> 7.2479317e-05
A48: SECTION 5 — WEIGHTED PIPELINE MODEL vs REP FORECAST vs ACTUAL (Q1 to Q3 2024)
A50: Model Forecast = Weighted_Pipeline column (column I) — pipeline adjusted by deal stage probability. Rep Forecast = what the rep manually submitted. Actual = what actually closed.
A51: Rep_ID | B51: Rep_Name | C51: Segment | D51: Rep Forecast £ | E51: Model Forecast £ | F51: Actual Closed £ | G51: Rep Accuracy % | H51: Model Accuracy % | I51: Model Better Than Rep?
A52: E01 | B52: James Whitfield | C52: Enterprise | D52: =SUMIFS(RAW_Forecast_Data!F:F,RAW_Forecast_Data!A:A,A52,RAW_Forecast_Data!E:E,"<>Q4 2024") -> 19225747 | E52: =SUMIFS(RAW_Forecast_Data!I:I,RAW_Forecast_Data!A:A,A52,RAW_Forecast_Data!E:E,"<>Q4 2024") -> 6103274.6 | F52: =SUMIFS(RAW_Forecast_Data!G:G,RAW_Forecast_Data!A:A,A52,RAW_Forecast_Data!E:E,"<>Q4 2024") -> 4793418.1 | G52: =IFERROR(1-ABS(D52-F52)/F52,"") -> -2.0108637 | H52: =IFERROR(1-ABS(E52-F52)/F52,"") -> 0.72673852 | I52: =IF(H52>G52,"Yes — Model Wins","No — Rep Wins") -> Yes — Model Wins
...

Sheet Data_Dictionary
A1: Column_Name | B1: Description | C1: Data_Type | D1: Expected_Format | E1: Example_Value | F1: Notes
A2: Rep_ID | B2: Unique identifier for each sales representative | C2: Text | D2: Letter + 2 digits e.g. E01, M03, S07 | E2: E01 | F2: E = Enterprise, M = Mid-Market, S = SMB
A3: Rep_Name | B3: Full name of the sales representative | C3: Text | D3: First name and surname | E3: James Whitfield | F3: Should be consistent across all rows for the same rep
A4: Segment | B4: The market segment the rep sells into | C4: Text | D4: One of three values: Enterprise, Mid-Market, SMB | E4: Enterprise | F4: Inconsistent formatting found in raw data — needs standardising
A5: Week_Ending_Date | B5: The Friday that marks the end of the working week the forecast covers | C5: Date | D5: DD/MM/YYYY | E5: 05/01/2024 | F5: Multiple date formats found in raw data — needs standardising
A6: Quarter | B6: The financial quarter the week falls within | C6: Text | D6: Q1 2024 / Q2 2024 / Q3 2024 / Q4 2024 | E6: Q1 2024 | F6: Inconsistent labels found in raw data — needs standardising
A7: Forecasted_Revenue | B7: The revenue the rep predicted they would close in that week | C7: Number | D7: Numeric value in GBP — no symbols or commas | E7: 125000 | F7: Some entries found as text strings e.g. £125,000 — needs cleaning
A8: Actual_Revenue_Closed | B8: The revenue the rep actually closed by end of that week | C8: Number | D8: Numeric value in GBP — no symbols or commas | E8: 118000 | F8: Blank for all Q4 2024 rows as the quarter had not yet closed at time of data export
A9: Pipeline_Value | B9: Total value of all active deals the rep currently has in progress | C9: Number | D9: Numeric value in GBP — no symbols or commas | E9: 450000 | F9: Should always be higher than Forecasted_Revenue — flag where it is not
A10: Weighted_Pipeline | B10: Pipeline value adjusted by probability of closing based on deal stage | C10: Number | D10: Numeric value in GBP — no symbols or commas | E10: 157500 | F10: Calculated field — should always be lower than Pipeline_Value
A11: Stage_Distribution | B11: Breakdown of where the rep's deals sit across the four pipeline stages | C11: Text | D11: Qualify:XX%, Propose:XX%, Negotiate:XX%, Close:XX% | E11: Qualify:20%,Propose:35%,Negotiate:30%,Close:15% | F11: Percentages should sum to 100%
A12: Deal_Count_Forecasted | B12: Number of individual deals the rep predicted they would close that week | C12: Number | D12: Whole number — no decimals | E12: 3 | F12: Should be reviewed alongside Forecasted_Revenue — large revenue on 1 deal is high risk
... A15: Notes | B15: Free text comment added by the rep or their manager about that week's forecast | C15: Text | D15: Free text — optional field | E15: Two deals slipped to next week | F15: Many blanks, N/A, n/a, and dashes present — treat all as blank during cleaning

Sheet Messy_Data_Log
A1: Column_Name | B1: Issue_Found | C1: Rows_Affected | D1: Example | E1: Impact | F1: Cleaning_Action_Planned
A2: Segment | B2: Inconsistent values, same segment entered in multiple different ways | C2: Multiple rows affected across all reps | D2: Enterprise, ENT, enterprise, Ent, ENTERPRISE all found in same column | E2: Segment-level analysis and filtering will break if not standardised | F2: Standardise all values to Enterprise, Mid-Market, or SMB only
A3: Week_Ending_Date | B3: Inconsistent date format - same date type entered in multiple formats | C3: Multiple rows affected across all reps | D3: 05/01/2024, 05-01-2024, 05 Jan 2024, 2024-01-05 all found in same column. | E3: Date-based calculations, sorting, and time series analysis will break if not standardised | F3: Standardise all dates to DD/MM/YYYY format
A4: Quarter | B4: Inconsistent labels, same quarter expressed in multiple different ways | C4: Multiple rows affected across all reps | D4: Q1 2024, Q1-2024, Q1, q1 2024, Jan-Mar 2024 all found in same column | E4: Quarter-level analysis and filtering will produce incorrect results if not standardised | F4: Standardise all values to Q1 2024, Q2 2024, Q3 2024, Q4 2024 format only
A5: Forecasted_Revenue | B5: Mixed data types, some values entered as text strings instead of numbers | C5: Approximately 47 rows affected | D5: £125,000 and GBP 45,000 and 45k found instead of plain numeric values | E5: Any formula or calculation using this column will return an error or be ignored where values are text | F5: Strip all symbols and text, convert all values to plain numbers
A6: Actual_Revenue_Closed | B6: Blank values, entire quarter missing actual revenue figures | C6: Approximately 241 rows affected ,all Q4 2024 rows | D6: Cells are blank where quarter has not yet closed at time of data export | E6: Forecast accuracy calculations will fail or be skewed if blanks are not handled correctly | F6: Exclude all Q4 2024 rows from any forecast accuracy calculations, do not delete them
A7: Forecast_Submitted_On_Time | B7: Inconsistent values - same Yes/No answer entered in multiple different ways | C7: Multiple rows affected across all reps | D7: Yes, yes, YES, Y, y, No, no, NO, N, Late, LATE all found in same column | E7: Submission compliance reporting will be inaccurate if values are not standardised | F7: Standardise all positive values to Yes and all negative values to No
A8: Notes | B8: Inconsistent blank values — empty notes recorded in multiple different ways | C8: Multiple rows affected across all reps | D8: Multiple rows affected across all reps | E8: Inconsistent nulls will cause issues if Notes column is used for any filtering or categorisation | F8: Standardise all variations of blank to a single blank empty cell
A9: Pipeline_Value | B9: Pipeline value lower than Forecasted_Revenue — no pipeline support for the forecast number | C9: Approximately 58 rows affected | D9: Pipeline_Value found to be less than 30% of Forecasted_Revenue in same row | E9: Indicates rep has submitted a forecast with no deals to support it — a key accuracy risk | F9: Flag these rows with a marker column during cleaning — do not delete them
A10: Actual_Revenue_Closed / Deal_Count_Closed | B10: Missing submissions — some reps have no row at all for certain weeks | C10: Approximately 50 to 60 rows missing across Callum Reid and Nathan Griffiths primarily | D10: No row exists for these reps for certain weeks — not a blank value but a missing record entirely | E10: Missing submissions mean these reps have gaps in their forecast accuracy history which will skew their performance metrics | F10: Note the missing weeks in analysis — do not fabricate data to fill gaps
